Workbook

Sheet Sheet1
A1: sample | B1: Type | C1: Y | D1: Zr | E1: Nb | F1: Ba | G1: La | H1: Ce | I1: Pr | J1: Nd | K1: Sm | L1: Eu | M1: Gd | N1: Tb | O1: Dy | P1: Ho | Q1: Er | R1: Tm | S1: Yb | T1: Lu | U1: Hf | V1: Ta | W1: Mo | X1: Sn | Y1: Sb | Z1: W | AA1: Pb | AB1: Th | AC1: U | AD1: δEu | AE1: δCe | AF1: (La/Yb)N | AG1: (Gd/Yb)N
A2: Turkina and Sukhorukov, 2017 | B2: Igneous | C2: 802 | D2: 17 | G2: 0.02 | H2: 0.07 | I2: 0.01 | J2: 0.68 | K2: 4.76 | L2: 0.08 | M2: 31.8 | O2: 103.7 | Q2: 86.1 | S2: 78.7 | T2: 9.7 | AD2: =L2/0.058/(K2/0.153*M2/0.2055)^0.5 -> 0.019879094 | AE2: =H2/0.612/(G2/0.237*I2/0.095)^0.5 -> 1.2135777 | AF2: =(G2/0.237)/(S2/0.17) -> 0.00018228706 | AG2: =(M2/0.2055)/(S2/0.17) -> 0.33426391
A3: Turkina and Sukhorukov, 2017 | B3: Igneous | C3: 859 | D3: 11 | G3: 0.02 | H3: 0.09 | I3: 0.02 | J3: 0.84 | K3: 2.63 | L3: 0.09 | M3: 15.6 | O3: 89.2 | Q3: 111.3 | S3: 118.1 | T3: 13.9 | AD3: =L3/0.058/(K3/0.153*M3/0.2055)^0.5 -> 0.042956211 | AE3: =H3/0.612/(G3/0.237*I3/0.095)^0.5 -> 1.1033088 | AF3: =(G3/0.237)/(S3/0.17) -> 0.00012147326 | AG3: =(M3/0.2055)/(S3/0.17) -> 0.10927273
A4: Turkina and Sukhorukov, 2017 | B4: Igneous | C4: 884 | D4: 6.2 | G4: 0.24 | H4: 0.84 | I4: 0.06 | J4: 0.64 | K4: 1.26 | L4: 0.06 | M4: 14.8 | O4: 99.3 | Q4: 102 | S4: 84.4 | T4: 8.3 | AD4: =L4/0.058/(K4/0.153*M4/0.2055)^0.5 -> 0.042477481 | AE4: =H4/0.612/(G4/0.237*I4/0.095)^0.5 -> 1.7162581 | AF4: =(G4/0.237)/(S4/0.17) -> 0.0020397144 | AG4: =(M4/0.2055)/(S4/0.17) -> 0.1450629
A5: Turkina and Sukhorukov, 2017 | B5: Igneous | C5: 268 | D5: 4.8 | G5: 0.01 | H5: 0.01 | I5: 0 | J5: 0.27 | K5: 2.84 | L5: 0.06 | M5: 33.2 | O5: 65.3 | Q5: 19.4 | S5: 15.9 | T5: 3.8 | AD5: =L5/0.058/(K5/0.153*M5/0.2055)^0.5 -> 0.01889064 | AF5: =(G5/0.237)/(S5/0.17) -> 0.00045113181 | AG5: =(M5/0.2055)/(S5/0.17) -> 1.7273409
A6: Clarke et al., 2013 | B6: Igneous | C6: 44.66 | D6: 13.19 | E6: 0.071 | F6: 0.36 | G6: 0.051 | H6: 0.234 | I6: 0.165 | J6: 3.57 | K6: 4.97 | L6: 2.46 | M6: 7.91 | O6: 8.8 | P6: 1.79 | Q6: 4.38 | S6: 3.95 | T6: 0.512 | U6: 0.203 | V6: 0.043 | AA6: 0.085 | AB6: 0.054 | AC6: 0.039 | AD6: =L6/0.058/(K6/0.153*M6/0.2055)^0.5 -> 1.1994781 | AE6: =H6/0.612/(G6/0.237*I6/0.095)^0.5 -> 0.62542228 | AF6: =(G6/0.237)/(S6/0.17) -> 0.0092613363 | AG6: =(M6/0.2055)/(S6/0.17) -> 1.6565955
A7: Clarke et al., 2013 | B7: Igneous | C7: 62.72 | D7: 32.16 | E7: 0.077 | F7: 0.47 | G7: 0.07 | H7: 0.331 | I7: 0.222 | J7: 3.47 | K7: 4.51 | L7: 2.09 | M7: 9.08 | O7: 11.49 | P7: 2.54 | Q7: 7.11 | S7: 6.95 | T7: 0.934 | U7: 0.456 | V7: 0.055 | AA7: 0.113 | AB7: 0.062 | AC7: 0.05 | AD7: =L7/0.058/(K7/0.153*M7/0.2055)^0.5 -> 0.99847852 | AE7: =H7/0.612/(G7/0.237*I7/0.095)^0.5 -> 0.65100907 | AF7: =(G7/0.237)/(S7/0.17) -> 0.0072246001 | AG7: =(M7/0.2055)/(S7/0.17) -> 1.0807821
A8: Clarke et al., 2013 | B8: Igneous | C8: 50.47 | D8: 19.99 | E8: 0.369 | F8: 0.39 | G8: 0.637 | H8: 2.61 | I8: 0.614 | J8: 4.72 | K8: 3.62 | L8: 2.06 | M8: 8.23 | O8: 8.52 | P8: 1.92 | Q8: 5.01 | S8: 6.11 | T8: 1 | U8: 0.57 | V8: 0.05 | AA8: 0.281 | AB8: 0.212 | AC8: 0.042 | AD8: =L8/0.058/(K8/0.153*M8/0.2055)^0.5 -> 1.1538163 | AE8: =H8/0.612/(G8/0.237*I8/0.095)^0.5 -> 1.023225 | AF8: =(G8/0.237)/(S8/0.17) -> 0.074782296 | AG8: =(M8/0.2055)/(S8/0.17) -> 1.1142836
A9: Clarke et al., 2013 | B9: Igneous | C9: 62.53 | D9: 11.26 | E9: 0.075 | F9: 0.46 | G9: 0.064 | H9: 0.102 | I9: 0.09 | J9: 2.34 | K9: 4.46 | L9: 2.3 | M9: 8.6 | O9: 10.74 | P9: 2.421 | Q9: 6.96 | S9: 7.54 | T9: 1.176 | U9: 0.172 | V9: 0.048 | AA9: 0.093 | AB9: 0.057 | AC9: 0.05 | AD9: =L9/0.058/(K9/0.153*M9/0.2055)^0.5 -> 1.1353632 | AE9: =H9/0.612/(G9/0.237*I9/0.095)^0.5 -> 0.32951371 | AF9: =(G9/0.237)/(S9/0.17) -> 0.0060884845 | AG9: =(M9/0.2055)/(S9/0.17) -> 0.94354844
A10: Clarke et al., 2013 | B10: Igneous | C10: 63 | D10: 16.31 | E10: 0.061 | F10: 0.39 | G10: 0.051 | H10: 0.247 | I10: 0.134 | J10: 3.82 | K10: 4.55 | L10: 2.67 | M10: 8.47 | O10: 11.23 | P10: 2.5 | Q10: 7.11 | S10: 7.66 | T10: 1.14 | U10: 0.345 | V10: 0.047 | AA10: 0.085 | AB10: 0.049 | AC10: 0.041 | AD10: =L10/0.058/(K10/0.153*M10/0.2055)^0.5 -> 1.3148842 | AE10: =H10/0.612/(G10/0.237*I10/0.095)^0.5 -> 0.73256138 | AF10: =(G10/0.237)/(S10/0.17) -> 0.0047757544 | AG10: =(M10/0.2055)/(S10/0.17) -> 0.9147275
A11: Clarke et al., 2013 | B11: Igneous | C11: 49.53 | D11: 17.84 | E11: 0.079 | F11: 0.46 | G11: 0.067 | H11: 0.149 | I11: 0.193 | J11: 2.36 | K11: 4.33 | L11: 2.47 | M11: 7.4 | O11: 9.12 | P11: 1.998 | Q11: 5.27 | S11: 6.57 | T11: 0.903 | U11: 0.19 | V11: 0.043 | AA11: 0.107 | AB11: 0.064 | AC11: 0.047 | AD11: =L11/0.058/(K11/0.153*M11/0.2055)^0.5 -> 1.3340152 | AE11: =H11/0.612/(G11/0.237*I11/0.095)^0.5 -> 0.3212586 | AF11: =(G11/0.237)/(S11/0.17) -> 0.0073149272 | AG11: =(M11/0.2055)/(S11/0.17) -> 0.93175868
A12: Clarke et al., 2013 | B12: Igneous | C12: 57.41 | D12: 33.18 | E12: 0.081 | F12: 1.22 | G12: 0.191 | H12: 0.589 | I12: 0.228 | J12: 3.24 | K12: 3.98 | L12: 1.747 | M12: 7.74 | O12: 10.78 | P12: 2.291 | Q12: 6.28 | S12: 6.52 | T12: 1.032 | U12: 0.424 | V12: 0.058 | AA12: 0.115 | AB12: 0.066 | AC12: 0.052 | AD12: =L12/0.058/(K12/0.153*M12/0.2055)^0.5 -> 0.96228679 | AE12: =H12/0.612/(G12/0.237*I12/0.095)^0.5 -> 0.69201537 | AF12: =(G12/0.237)/(S12/0.17) -> 0.021012917 | AG12: =(M12/0.2055)/(S12/0.17) -> 0.9820429
A13: Clarke et al., 2013 | B13: Igneous | C13: 66.63 | D13: 14.52 | E13: 0.065 | F13: 0.4 | G13: 0.052 | H13: 0.142 | I13: 0.134 | J13: 3.02 | K13: 4.09 | L13: 2.28 | M13: 8.28 | O13: 11.65 | P13: 2.84 | Q13: 7.84 | S13: 8.08 | T13: 1.199 | U13: 0.163 | V13: 0.043 | AA13: 0.085 | AB13: 0.053 | AC13: 0.492 | AD13: =L13/0.058/(K13/0.153*M13/0.2055)^0.5 -> 1.1977927 | AE13: =H13/0.612/(G13/0.237*I13/0.095)^0.5 -> 0.41707948 | AF13: =(G13/0.237)/(S13/0.17) -> 0.0046162844 | AG13: =(M13/0.2055)/(S13/0.17) -> 0.84772711
A14: Clarke et al., 2013 | B14: Igneous | C14: 45.59 | D14: 19.24 | E14: 0.076 | F14: 0.49 | G14: 0.062 | H14: 0.263 | I14: 0.162 | J14: 3.18 | K14: 4.1 | L14: 2.46 | M14: 8.37 | O14: 8.97 | P14: 1.79 | Q14: 4.31 | S14: 3.8 | T14: 0.486 | U14: 0.218 | V14: 0.054 | AA14: 0.098 | AB14: 0.055 | AC14: 0.046 | AD14: =L14/0.058/(K14/0.153*M14/0.2055)^0.5 -> 1.2838198 | AE14: =H14/0.612/(G14/0.237*I14/0.095)^0.5 -> 0.64340873 | AF14: =(G14/0.237)/(S14/0.17) -> 0.011703309 | AG14: =(M14/0.2055)/(S14/0.17) -> 1.8221283
A15: Clarke et al., 2013 | B15: Igneous | C15: 39.36 | D15: 13.34 | E15: 0.037 | F15: 2.92 | G15: 0.064 | H15: 0.278 | I15: 0.1054 | J15: 1.559 | K15: 3.25 | L15: 1.92 | M15: 6.77 | O15: 7.9 | P15: 1.509 | Q15: 3.98 | S15: 3.34 | T15: 0.447 | U15: 0.178 | V15: 0.0264 | AA15: 0.104 | AB15: 0.029 | AC15: 0.0256 | AD15: =L15/0.058/(K15/0.153*M15/0.2055)^0.5 -> 1.251379 | AE15: =H15/0.612/(G15/0.237*I15/0.095)^0.5 -> 0.82988718 | AF15: =(G15/0.237)/(S15/0.17) -> 0.013744663 | AG15: =(M15/0.2055)/(S15/0.17) -> 1.6767924
A16: Clarke et al., 2013 | B16: Igneous | C16: 41.38 | D16: 6.79 | E16: 0.031 | F16: 0.144 | G16: 0.049 | H16: 0.125 | I16: 0.0553 | J16: 1.624 | K16: 2.94 | L16: 2.006 | M16: 6.25 | O16: 7.36 | P16: 1.51 | Q16: 4.18 | S16: 3.94 | T16: 0.558 | U16: 0.066 | V16: 0.019 | AA16: 0.032 | AB16: 0.0687 | AC16: 0.0191 | AD16: =L16/0.058/(K16/0.153*M16/0.2055)^0.5 -> 1.4306747 | AE16: =H16/0.612/(G16/0.237*I16/0.095)^0.5 -> 0.58875412 | AF16: =(G16/0.237)/(S16/0.17) -> 0.0089207308 | AG16: =(M16/0.2055)/(S16/0.17) -> 1.312263
A17: Clarke et al., 2013 | B17: Igneous | C17: 24.95 | D17: 13.85 | E17: 0.036 | F17: 0.164 | G17: 0.0203 | H17: 0.159 | I17: 0.143 | J17: 2.31 | K17: 3.21 | L17: 2.02 | M17: 5.62 | O17: 5.2 | P17: 0.962 | Q17: 2.47 | S17: 2.042 | T17: 0.273 | U17: 0.146 | V17: 0.0163 | AA17: 0.034 | AB17: 0.0195 | AC17: 0.02 | AD17: =L17/0.058/(K17/0.153*M17/0.2055)^0.5 -> 1.4539663 | AE17: =H17/0.612/(G17/0.237*I17/0.095)^0.5 -> 0.72354516 | AF17: =(G17/0.237)/(S17/0.17) -> 0.007130843 | AG17: =(M17/0.2055)/(S17/0.17) -> 2.2767622
... A64: Clarke et al., 2013 | B64: Igneous | C64: 47.87 | D64: 11.87 | E64: 0.033 | F64: 0.147 | G64: 0.0206 | H64: 0.079 | I64: 0.0752 | J64: 1.58 | K64: 2.69 | L64: 1.781 | M64: 5.87 | O64: 8.69 | P64: 1.761 | Q64: 5.01 | S64: 4.51 | T64: 0.612 | U64: 0.224 | V64: 0.0206 | AA64: 0.037 | AB64: 0.0233 | AC64: 0.0203 | AD64: =L64/0.058/(K64/0.153*M64/0.2055)^0.5 -> 1.3702265 | AE64: =H64/0.612/(G64/0.237*I64/0.095)^0.5 -> 0.49211785 | AF64: =(G64/0.237)/(S64/0.17) -> 0.0032763573 | AG64: =(M64/0.2055)/(S64/0.17) -> 1.0767098
A65: Mahdy et al., 2023 | B65: Igneous | C65: 2109.55 | D65: 3.53 | H65: 0.17 | I65: 0.18 | J65: 3.61 | K65: 19.28 | L65: 1.41 | M65: 79.72 | N65: 35.41 | P65: 89.4 | Q65: 344.08 | R65: 69.7 | S65: 615.06 | T65: 99.1 | AD65: =L65/0.058/(K65/0.153*M65/0.2055)^0.5 -> 0.10995262 | AG65: =(M65/0.2055)/(S65/0.17) -> 0.10722274
A66: Mahdy et al., 2023 | B66: Igneous | C66: 1887.34 | D66: 1.79 | H66: 0.21 | I66: 0.19 | J66: 2.93 | K66: 12.03 | L66: 0.95 | M66: 49 | N66: 25.97 | P66: 83.11 | Q66: 337.01 | R66: 73.57 | S66: 679.04 | T66: 106.17 | AD66: =L66/0.058/(K66/0.153*M66/0.2055)^0.5 -> 0.11962347 | AG66: =(M66/0.2055)/(S66/0.17) -> 0.059694981
A67: Mahdy et al., 2023 | B67: Igneous | C67: 2639.24 | H67: 0.09 | I67: 0.08 | J67: 1.21 | K67: 5.08 | L67: 0.58 | M67: 21.24 | N67: 15.78 | P67: 107.54 | Q67: 640.44 | R67: 185.35 | S67: 2115.33 | T67: 409.33 | U67: 0.98 | AD67: =L67/0.058/(K67/0.153*M67/0.2055)^0.5 -> 0.17070354 | AG67: =(M67/0.2055)/(S67/0.17) -> 0.0083064122
A68: Mahdy et al., 2023 | B68: Igneous | C68: 2668.73 | D68: 1.1 | H68: 0.1 | I68: 0.09 | J68: 1.07 | K68: 4.78 | L68: 0.57 | M68: 22.79 | N68: 15.88 | P68: 104.48 | Q68: 611.82 | R68: 178.67 | S68: 2059.61 | T68: 402.5 | AD68: =L68/0.058/(K68/0.153*M68/0.2055)^0.5 -> 0.16695998 | AG68: =(M68/0.2055)/(S68/0.17) -> 0.0091536948
A69: Mahdy et al., 2023 | B69: Igneous | C69: 3921.19 | D69: 3.54 | H69: 0.2 | I69: 0.09 | J69: 1.31 | K69: 6.27 | L69: 1.66 | M69: 37.3 | N69: 28.49 | P69: 187.29 | Q69: 994.26 | R69: 264.1 | S69: 2668.11 | T69: 482.45 | AD69: =L69/0.058/(K69/0.153*M69/0.2055)^0.5 -> 0.33185131 | AG69: =(M69/0.2055)/(S69/0.17) -> 0.011564908
A70: Mahdy et al., 2023 | B70: Igneous | C70: 5095.19 | D70: 4.29 | H70: 0.24 | I70: 0.31 | J70: 3.87 | K70: 10.4 | L70: 0.5 | M70: 45.65 | N70: 31.35 | P70: 194.34 | Q70: 1118.33 | R70: 315.67 | S70: 3463.63 | T70: 671.07 | U70: 1.51 | AD70: =L70/0.058/(K70/0.153*M70/0.2055)^0.5 -> 0.070154669 | AG70: =(M70/0.2055)/(S70/0.17) -> 0.010903009
A71: Mahdy et al., 2023 | B71: Igneous | C71: 4674.48 | D71: 2.23 | H71: 0.11 | I71: 0.1 | J71: 1.43 | K71: 8.37 | L71: 1.11 | M71: 47.97 | N71: 34.19 | P71: 199.52 | Q71: 981.38 | R71: 232.37 | S71: 2217.2 | T71: 375.17 | U71: 1.38 | AC71: 0.08 | AD71: =L71/0.058/(K71/0.153*M71/0.2055)^0.5 -> 0.16935539 | AG71: =(M71/0.2055)/(S71/0.17) -> 0.017897894
A72: Mahdy et al., 2023 | B72: Igneous | C72: 9845.72 | D72: 3.29 | H72: 0.16 | I72: 0.13 | J72: 3.45 | K72: 18.16 | L72: 2.11 | M72: 103.41 | N72: 68.38 | P72: 307.77 | Q72: 1337.87 | R72: 290.36 | S72: 2543.39 | T72: 391.07 | U72: 1.72 | AC72: 0.12 | AD72: =L72/0.058/(K72/0.153*M72/0.2055)^0.5 -> 0.14885619 | AG72: =(M72/0.2055)/(S72/0.17) -> 0.033634631
A73: Mahdy et al., 2023 | B73: Igneous | C73: 10462.92 | D73: 3.48 | H73: 0.28 | I73: 0.3 | J73: 5.01 | K73: 23.46 | L73: 2.58 | M73: 119.79 | N73: 73.09 | P73: 320.72 | Q73: 1438.89 | R73: 323.39 | S73: 2994.19 | T73: 486.12 | U73: 2.54 | AB73: 1.1 | AC73: 0.13 | AD73: =L73/0.058/(K73/0.153*M73/0.2055)^0.5 -> 0.14878839 | AG73: =(M73/0.2055)/(S73/0.17) -> 0.033096213
A74: Mahdy et al., 2023 | B74: Igneous | C74: 12637.93 | D74: 3.27 | H74: 0.14 | I74: 0.25 | J74: 4.19 | K74: 20.88 | L74: 2.36 | M74: 122.9 | N74: 77.76 | P74: 392.37 | Q74: 1930.28 | R74: 452.36 | S74: 4377.61 | T74: 765.52 | U74: 2.33 | AC74: 0.14 | AD74: =L74/0.058/(K74/0.153*M74/0.2055)^0.5 -> 0.1424277 | AG74: =(M74/0.2055)/(S74/0.17) -> 0.023224796
A75: Mahdy et al., 2023 | B75: Igneous | C75: 11699.91 | D75: 6.08 | H75: 0.31 | I75: 0.24 | J75: 4.56 | K75: 20.48 | L75: 2.14 | M75: 113.41 | N75: 73.6 | P75: 373.87 | Q75: 1831.02 | R75: 436.61 | S75: 4258.97 | T75: 751.16 | AD75: =L75/0.058/(K75/0.153*M75/0.2055)^0.5 -> 0.13575216 | AG75: =(M75/0.2055)/(S75/0.17) -> 0.022028446
A76: Mahdy et al., 2023 | B76: Igneous | C76: 11979.27 | D76: 4.06 | H76: 0.29 | I76: 0.23 | J76: 4.18 | K76: 22.88 | L76: 2.4 | M76: 119.59 | N76: 76.26 | P76: 403.48 | Q76: 2044.96 | R76: 492.39 | S76: 4902.88 | T76: 898.54 | U76: 2.23 | AB76: 1.02 | AC76: 0.14 | AD76: =L76/0.058/(K76/0.153*M76/0.2055)^0.5 -> 0.14026827 | AG76: =(M76/0.2055)/(S76/0.17) -> 0.02017812
A77: Mahdy et al., 2023 | B77: Igneous | C77: 7670.14 | D77: 3 | H77: 0.14 | I77: 0.12 | J77: 2.48 | K77: 12.26 | L77: 1.75 | M77: 74.87 | N77: 51.15 | P77: 241.15 | Q77: 1031.97 | R77: 214.43 | S77: 1828.74 | T77: 273.25 | U77: 1.84 | AC77: 0.08 | AD77: =L77/0.058/(K77/0.153*M77/0.2055)^0.5 -> 0.17658855 | AG77: =(M77/0.2055)/(S77/0.17) -> 0.033868266
A78: Mahdy et al., 2023 | B78: Igneous | C78: 6207.78 | D78: 2.36 | H78: 0.14 | I78: 0.12 | J78: 1.53 | K78: 9.44 | L78: 1.63 | M78: 56.82 | N78: 42.57 | P78: 248.77 | Q78: 1241.5 | R78: 291.58 | S78: 2775.53 | T78: 485.01 | U78: 1.33 | AC78: 0.08 | AD78: =L78/0.058/(K78/0.153*M78/0.2055)^0.5 -> 0.21516649 | AG78: =(M78/0.2055)/(S78/0.17) -> 0.016935281
A79: Mahdy et al., 2023 | B79: Igneous | C79: 2822.5 | D79: 1.44 | H79: 0.07 | J79: 1.34 | K79: 4.74 | L79: 0.57 | M79: 23.84 | N79: 16.19 | P79: 102.8 | Q79: 607.63 | R79: 177 | S79: 2091.57 | T79: 439.64 | U79: 0.84 | AD79: =L79/0.058/(K79/0.153*M79/0.2055)^0.5 -> 0.16392915 | AG79: =(M79/0.2055)/(S79/0.17) -> 0.0094291152
A80: Mahdy et al., 2023 | B80: Igneous | C80: 3041.26 | D80: 2.33 | H80: 0.11 | I80: 0.09 | J80: 1.48 | K80: 6.18 | L80: 0.67 | M80: 33.03 | N80: 24.67 | P80: 182.72 | Q80: 1127.27 | R80: 316.68 | S80: 3470.78 | T80: 695.18 | U80: 0.94 | AC80: 0.06 | AD80: =L80/0.058/(K80/0.153*M80/0.2055)^0.5 -> 0.14336724 | AG80: =(M80/0.2055)/(S80/0.17) -> 0.0078726072
A81: Mahdy et al., 2023 | B81: Igneous | C81: 1545.43 | D81: 1.44 | H81: 0.16 | I81: 0.11 | J81: 2.17 | K81: 9.35 | L81: 0.79 | M81: 39.1 | N81: 20.56 | P81: 66.95 | Q81: 274.77 | R81: 60.03 | S81: 527.43 | T81: 81.1 | AD81: =L81/0.058/(K81/0.153*M81/0.2055)^0.5 -> 0.12631547 | AG81: =(M81/0.2055)/(S81/0.17) -> 0.061326619
A82: Mahdy et al., 2023 | B82: Igneous | C82: 2378.69 | H82: 0.08 | I82: 0.12 | J82: 1.1 | K82: 3.96 | L82: 0.5 | M82: 19.18 | N82: 13.81 | P82: 89.85 | Q82: 548.06 | R82: 161.18 | S82: 1908.27 | T82: 388.65 | U82: 0.98 | AD82: =L82/0.058/(K82/0.153*M82/0.2055)^0.5 -> 0.17539683 | AG82: =(M82/0.2055)/(S82/0.17) -> 0.0083146864
A83: Mahdy et al., 2023 | B83: Igneous | C83: 2800 | D83: 5.63 | H83: 0.26 | I83: 0.15 | J83: 1.35 | K83: 5.93 | L83: 0.67 | M83: 28.62 | N83: 20.58 | P83: 154.52 | Q83: 940.48 | R83: 274.14 | S83: 3169.64 | T83: 638.42 | AD83: =L83/0.058/(K83/0.153*M83/0.2055)^0.5 -> 0.15723031 | AG83: =(M83/0.2055)/(S83/0.17) -> 0.0074695904
A84: Mahdy et al., 2023 | B84: Igneous | C84: 3936.35 | H84: 0.19 | I84: 0.11 | J84: 1.89 | K84: 7.71 | L84: 0.64 | M84: 39.75 | N84: 28.77 | P84: 194.57 | Q84: 1070.29 | R84: 280.15 | S84: 2915.67 | T84: 552.58 | AC84: 0.16 | AD84: =L84/0.058/(K84/0.153*M84/0.2055)^0.5 -> 0.11176552 | AG84: =(M84/0.2055)/(S84/0.17) -> 0.011278098
A85: Mahdy et al., 2023 | B85: Igneous | C85: 4787.06 | H85: 0.08 | J85: 1.3 | K85: 8.65 | L85: 2.16 | M85: 48.16 | N85: 34.89 | P85: 209.21 | Q85: 1062.6 | R85: 256.17 | S85: 2437.69 | T85: 399.85 | U85: 1.52 | AD85: =L85/0.058/(K85/0.153*M85/0.2055)^0.5 -> 0.32353859 | AG85: =(M85/0.2055)/(S85/0.17) -> 0.016343501
A86: Mahdy et al., 2023 | B86: Igneous | C86: 2821.68 | H86: 0.08 | I86: 0.07 | J86: 1.3 | K86: 5.44 | L86: 0.57 | M86: 24.6 | N86: 16.76 | P86: 111.97 | Q86: 693.82 | R86: 199.75 | S86: 2305.31 | T86: 478.93 | AD86: =L86/0.058/(K86/0.153*M86/0.2055)^0.5 -> 0.15063694 | AG86: =(M86/0.2055)/(S86/0.17) -> 0.0088276045
...

Sheet Reference
A1: Reference
A2: Bhattacharyya A, Rubatto D and Hermann J. 2026. Garnet trace element systematics in an amphibolite- to granulite-facies metapelitic sequence (Ivrea-Verbano Zone, Italy). Contributions to Mineralogy and Petrology, 181, 80
A3: Cheng H, King RL, Nakamura E, Vervoort JD, Zheng YF, Ota T, Wu YB, Kobayashi K and Zhou ZY. 2009. Transitional time of oceanic to continental subduction in the Dabie orogen: Constraints from U–Pb, Lu–Hf, Sm–Nd and Ar–Ar multichronometric dating. Lithos, 110(1): 327-342
A4: Clarke GL, Daczko NR and Miescher D. 2013. Identifying Relic Igneous Garnet and Clinopyroxene in Eclogite and Granulite, Breaksea Orthogneiss, New Zealand. Journal of Petrology, 54(9): 1921-1938
A5: Cravinho A, Rosa D, Relvas JMRS, Solá AR, Pereira I, Paquette J-L, Borba ML, Tassinari CCG, Chew D, Drakou F, Breiter K and Araujo V. 2024. From source to surface: clues from garnet-bearing Carboniferous silicic volcanic rocks, Iberian Pyrite Belt, Portugal. Contributions to Mineralogy and Petrology, 179(4): 32
A6: Culí L, Solé J, Campeny M and Oalmann JAG. 2021. High-Temperature Metamorphic Garnets from Grenvillian Granulites of Southwestern Oaxacan Complex (Southern Mexico): Petrology, Geochemistry, Geothermobarometry, and Tectonic Implications. Minerals, 11(8): 805
A7: Dorais MJ and Campbell S. 2022. Peritectic and phenocrystic garnet accumulation and the origin of strongly peraluminous granitic rocks: The Flagstaff Lake Igneous Complex, Maine. Lithos, 418-419: 106680
A8: Dorais MJ and Tubrett M. 2012. Detecting Peritectic Garnet in the Peraluminous Cardigan Pluton, New Hampshire. Journal of Petrology, 53(2): 299-324
A9: Feng Y, Cen J, Liang T, Wang M, Tan X, Hao Y and Yan S. 2023. Lithium, Phosphorus, and rare earth elements in magmatic garnets from granitic Pegmatites: Coupled substitution and petrogenetic implications. Ore Geology Reviews, 153: 105284
A10: Gaidies F, Morneau YE, Petts DC, Jackson SE, Zagorevski A and Ryan JJ. 2021. Major and trace element mapping of garnet: Unravelling the conditions, timing and rates of metamorphism of the Snowcap assemblage, west-central Yukon. Journal of Metamorphic Geology, 39(2): 133-164
A11: Gao LE, Zeng LS, Zhao LH, Hu MY, Wang L, Gao JH, Shang Z. 2017. Multiphase growth of garnet in gneisses from the Himalayan orogenic belt. Acta Petrologica Sinica, 33(12): 3729–3740
A12: Godet A, Guilmette C, Smit M, Maneta V, Fournier-Roy F and Musiyachenko K. 2025. Insights into garnet growth in S-type granite from Lu–Hf dating and trace element mapping. Contributions to Mineralogy and Petrology, 180(6): 36
... A47: 王浩铮, 张华锋和翟明国. 2015. 基性麻粒岩造岩矿物微量元素再分配特征及其对变质历史的指示作用:以胶北地体高压麻粒岩为例. 岩石学报, 31(6): 1694-1710
AA48: 0.052 | AB48: 0.157 | AC48: 0.03 | AD48: =Sheet1!L4249/0.058/(Sheet1!K4249/0.153*Sheet1!M4249/0.2055)^0.5 -> 0.470312 | AE48: =Sheet1!H4249/0.612/(Sheet1!G4249/0.237*Sheet1!I4249/0.095)^0.5 -> 0.97527081 | AF48: =(Sheet1!G4249/0.237)/(Sheet1!S4249/0.17) -> 0.0053338755 | AG48: =(Sheet1!M4249/0.2055)/(Sheet1!S4249/0.17) -> 1.2873811
AA49: 0.421 | AB49: 27.98 | AC49: 1.156 | AD49: =Sheet1!L4250/0.058/(Sheet1!K4250/0.153*Sheet1!M4250/0.2055)^0.5 -> 0.32741557 | AE49: =Sheet1!H4250/0.612/(Sheet1!G4250/0.237*Sheet1!I4250/0.095)^0.5 -> 0.92482957 | AF49: =(Sheet1!G4250/0.237)/(Sheet1!S4250/0.17) -> 0.5504239 | AG49: =(Sheet1!M4250/0.2055)/(Sheet1!S4250/0.17) -> 0.44222235
AA50: 0.041 | AB50: 0.277 | AC50: 0.112 | AD50: =Sheet1!L4251/0.058/(Sheet1!K4251/0.153*Sheet1!M4251/0.2055)^0.5 -> 0.52551312 | AE50: =Sheet1!H4251/0.612/(Sheet1!G4251/0.237*Sheet1!I4251/0.095)^0.5 -> 1.1082006 | AF50: =(Sheet1!G4251/0.237)/(Sheet1!S4251/0.17) -> 0.029618153 | AG50: =(Sheet1!M4251/0.2055)/(Sheet1!S4251/0.17) -> 1.4525564
AA51: 0.113 | AB51: 12.19 | AC51: 1.551 | AD51: =Sheet1!L4252/0.058/(Sheet1!K4252/0.153*Sheet1!M4252/0.2055)^0.5 -> 0.34712472 | AE51: =Sheet1!H4252/0.612/(Sheet1!G4252/0.237*Sheet1!I4252/0.095)^0.5 -> 0.94301667 | AF51: =(Sheet1!G4252/0.237)/(Sheet1!S4252/0.17) -> 0.64257416 | AG51: =(Sheet1!M4252/0.2055)/(Sheet1!S4252/0.17) -> 1.2158021
AA52: 0.056 | AB52: 0.231 | AC52: 0.288 | AD52: =Sheet1!L4253/0.058/(Sheet1!K4253/0.153*Sheet1!M4253/0.2055)^0.5 -> 0.4275457 | AE52: =Sheet1!H4253/0.612/(Sheet1!G4253/0.237*Sheet1!I4253/0.095)^0.5 -> 1.0004774 | AF52: =(Sheet1!G4253/0.237)/(Sheet1!S4253/0.17) -> 0.0070023503 | AG52: =(Sheet1!M4253/0.2055)/(Sheet1!S4253/0.17) -> 0.69469145
AB53: 0.03 | AC53: 0.042 | AD53: =Sheet1!L4254/0.058/(Sheet1!K4254/0.153*Sheet1!M4254/0.2055)^0.5 -> 0.41857672 | AE53: =Sheet1!H4254/0.612/(Sheet1!G4254/0.237*Sheet1!I4254/0.095)^0.5 -> 1.8496169 | AF53: =(Sheet1!G4254/0.237)/(Sheet1!S4254/0.17) -> 0.0011712926 | AG53: =(Sheet1!M4254/0.2055)/(Sheet1!S4254/0.17) -> 0.5631626
AA54: 0.094 | AB54: 1.153 | AC54: 2.693 | AD54: =Sheet1!L4255/0.058/(Sheet1!K4255/0.153*Sheet1!M4255/0.2055)^0.5 -> 0.48377582 | AE54: =Sheet1!H4255/0.612/(Sheet1!G4255/0.237*Sheet1!I4255/0.095)^0.5 -> 0.86470851 | AF54: =(Sheet1!G4255/0.237)/(Sheet1!S4255/0.17) -> 0.00055799967 | AG54: =(Sheet1!M4255/0.2055)/(Sheet1!S4255/0.17) -> 0.22461359
AA55: 0.231 | AB55: 0.125 | AC55: 0.047 | AD55: =Sheet1!L4256/0.058/(Sheet1!K4256/0.153*Sheet1!M4256/0.2055)^0.5 -> 0.46492888 | AE55: =Sheet1!H4256/0.612/(Sheet1!G4256/0.237*Sheet1!I4256/0.095)^0.5 -> 1.1553187 | AG55: =(Sheet1!M4256/0.2055)/(Sheet1!S4256/0.17) -> 0.068382187
AA56: 0.033 | AB56: 0 | AC56: 0.015 | AD56: =Sheet1!L4257/0.058/(Sheet1!K4257/0.153*Sheet1!M4257/0.2055)^0.5 -> 0.52037072 | AE56: =Sheet1!H4257/0.612/(Sheet1!G4257/0.237*Sheet1!I4257/0.095)^0.5 -> 0.37400341 | AG56: =(Sheet1!M4257/0.2055)/(Sheet1!S4257/0.17) -> 0.086377381
AA57: 0.008 | AB57: 0 | AC57: 0.002 | AD57: =Sheet1!L4258/0.058/(Sheet1!K4258/0.153*Sheet1!M4258/0.2055)^0.5 -> 0.64515908 | AE57: =Sheet1!H4258/0.612/(Sheet1!G4258/0.237*Sheet1!I4258/0.095)^0.5 -> 0.13429047 | AG57: =(Sheet1!M4258/0.2055)/(Sheet1!S4258/0.17) -> 0.043168283
AA58: 0.051 | AB58: 0.006 | AC58: 0.015 | AD58: =Sheet1!L4259/0.058/(Sheet1!K4259/0.153*Sheet1!M4259/0.2055)^0.5 -> 0.61376457 | AE58: =Sheet1!H4259/0.612/(Sheet1!G4259/0.237*Sheet1!I4259/0.095)^0.5 -> 0.2696977 | AG58: =(Sheet1!M4259/0.2055)/(Sheet1!S4259/0.17) -> 0.084528332
AA59: 0.077 | AB59: 0 | AC59: 0.004 | AD59: =Sheet1!L4260/0.058/(Sheet1!K4260/0.153*Sheet1!M4260/0.2055)^0.5 -> 0.5009666 | AG59: =(Sheet1!M4260/0.2055)/(Sheet1!S4260/0.17) -> 0.039283103
AA60: 0.039 | AB60: 0 | AC60: 0.03 | AD60: =Sheet1!L4261/0.058/(Sheet1!K4261/0.153*Sheet1!M4261/0.2055)^0.5 -> 0.81582318 | AG60: =(Sheet1!M4261/0.2055)/(Sheet1!S4261/0.17) -> 0.71581341
AA61: 0.086 | AB61: 0.013 | AC61: 0.025 | AD61: =Sheet1!L4262/0.058/(Sheet1!K4262/0.153*Sheet1!M4262/0.2055)^0.5 -> 0.88101794 | AE61: =Sheet1!H4262/0.612/(Sheet1!G4262/0.237*Sheet1!I4262/0.095)^0.5 -> 0.23115766 | AF61: =(Sheet1!G4262/0.237)/(Sheet1!S4262/0.17) -> 0.0025921286 | AG61: =(Sheet1!M4262/0.2055)/(Sheet1!S4262/0.17) -> 4.9326125
AA62: 0.037 | AB62: 0 | AC62: 0.031 | AD62: =Sheet1!L4263/0.058/(Sheet1!K4263/0.153*Sheet1!M4263/0.2055)^0.5 -> 1.1017156 | AG62: =(Sheet1!M4263/0.2055)/(Sheet1!S4263/0.17) -> 1.185339
AB63: 0.012 | AC63: 0.012 | AD63: =Sheet1!L4264/0.058/(Sheet1!K4264/0.153*Sheet1!M4264/0.2055)^0.5 -> 2.3640924 | AE63: =Sheet1!H4264/0.612/(Sheet1!G4264/0.237*Sheet1!I4264/0.095)^0.5 -> 0.23123369 | AF63: =(Sheet1!G4264/0.237)/(Sheet1!S4264/0.17) -> 0.0097591779 | AG63: =(Sheet1!M4264/0.2055)/(Sheet1!S4264/0.17) -> 5.0839333
AA64: 0.023 | AB64: 0.006 | AC64: 0.019 | AD64: =Sheet1!L4265/0.058/(Sheet1!K4265/0.153*Sheet1!M4265/0.2055)^0.5 -> 0.83289097 | AE64: =Sheet1!H4265/0.612/(Sheet1!G4265/0.237*Sheet1!I4265/0.095)^0.5 -> 0.3920437 | AF64: =(Sheet1!G4265/0.237)/(Sheet1!S4265/0.17) -> 0.0013047741 | AG64: =(Sheet1!M4265/0.2055)/(Sheet1!S4265/0.17) -> 1.8847319
AA65: 0.054 | AB65: 0 | AC65: 0.002 | AD65: =Sheet1!L4266/0.058/(Sheet1!K4266/0.153*Sheet1!M4266/0.2055)^0.5 -> 0.47528574 | AG65: =(Sheet1!M4266/0.2055)/(Sheet1!S4266/0.17) -> 0.26791639
AA66: 0.231 | AB66: 1.895 | AC66: 0.685 | AD66: =Sheet1!L4267/0.058/(Sheet1!K4267/0.153*Sheet1!M4267/0.2055)^0.5 -> 1.5289445 | AE66: =Sheet1!H4267/0.612/(Sheet1!G4267/0.237*Sheet1!I4267/0.095)^0.5 -> 0.58111394 | AF66: =(Sheet1!G4267/0.237)/(Sheet1!S4267/0.17) -> 0.06180155 | AG66: =(Sheet1!M4267/0.2055)/(Sheet1!S4267/0.17) -> 1.0886772
AA67: 0.73 | AB67: 4.314 | AC67: 0.305 | AD67: =Sheet1!L4268/0.058/(Sheet1!K4268/0.153*Sheet1!M4268/0.2055)^0.5 -> 1.0262268 | AE67: =Sheet1!H4268/0.612/(Sheet1!G4268/0.237*Sheet1!I4268/0.095)^0.5 -> 0.45845407 | AF67: =(Sheet1!G4268/0.237)/(Sheet1!S4268/0.17) -> 0.028259185 | AG67: =(Sheet1!M4268/0.2055)/(Sheet1!S4268/0.17) -> 0.46552115
AA68: 0.078 | AB68: 0 | AC68: 0.023 | AD68: =Sheet1!L4269/0.058/(Sheet1!K4269/0.153*Sheet1!M4269/0.2055)^0.5 -> 0.71515433 | AF68: =(Sheet1!G4269/0.237)/(Sheet1!S4269/0.17) -> 0.00070631249 | AG68: =(Sheet1!M4269/0.2055)/(Sheet1!S4269/0.17) -> 1.6164875
AA69: 0.014 | AB69: 0.006 | AC69: 0 | AD69: =Sheet1!L4270/0.058/(Sheet1!K4270/0.153*Sheet1!M4270/0.2055)^0.5 -> 0.8970569 | AG69: =(Sheet1!M4270/0.2055)/(Sheet1!S4270/0.17) -> 1.8604338
AA70: 0.046 | AB70: 0 | AC70: 0.023 | AD70: =Sheet1!L4271/0.058/(Sheet1!K4271/0.153*Sheet1!M4271/0.2055)^0.5 -> 0.78261402 | AE70: =Sheet1!H4271/0.612/(Sheet1!G4271/0.237*Sheet1!I4271/0.095)^0.5 -> 0.83769739 | AG70: =(Sheet1!M4271/0.2055)/(Sheet1!S4271/0.17) -> 1.0534683
AA71: 1.819 | AB71: 0.326 | AC71: 0.309 | AD71: =Sheet1!L4272/0.058/(Sheet1!K4272/0.153*Sheet1!M4272/0.2055)^0.5 -> 2.0160145 | AE71: =Sheet1!H4272/0.612/(Sheet1!G4272/0.237*Sheet1!I4272/0.095)^0.5 -> 0.57026406 | AF71: =(Sheet1!G4272/0.237)/(Sheet1!S4272/0.17) -> 0.02730753 | AG71: =(Sheet1!M4272/0.2055)/(Sheet1!S4272/0.17) -> 0.42142007
AA72: 0.105 | AB72: 0.062 | AC72: 0.024 | AD72: =Sheet1!L4273/0.058/(Sheet1!K4273/0.153*Sheet1!M4273/0.2055)^0.5 -> 2.7114492 | AE72: =Sheet1!H4273/0.612/(Sheet1!G4273/0.237*Sheet1!I4273/0.095)^0.5 -> 0.55877844 | AF72: =(Sheet1!G4273/0.237)/(Sheet1!S4273/0.17) -> 0.01081178 | AG72: =(Sheet1!M4273/0.2055)/(Sheet1!S4273/0.17) -> 0.75509359
AA73: 0.147 | AB73: 0.136 | AC73: 0.076 | AD73: =Sheet1!L4274/0.058/(Sheet1!K4274/0.153*Sheet1!M4274/0.2055)^0.5 -> 3.7754767 | AE73: =Sheet1!H4274/0.612/(Sheet1!G4274/0.237*Sheet1!I4274/0.095)^0.5 -> 0.55147305 | AF73: =(Sheet1!G4274/0.237)/(Sheet1!S4274/0.17) -> 0.027867568 | AG73: =(Sheet1!M4274/0.2055)/(Sheet1!S4274/0.17) -> 0.38131867
AA74: 0.337 | AB74: 0.158 | AC74: 0.064 | AD74: =Sheet1!L4275/0.058/(Sheet1!K4275/0.153*Sheet1!M4275/0.2055)^0.5 -> 3.3165789 | AE74: =Sheet1!H4275/0.612/(Sheet1!G4275/0.237*Sheet1!I4275/0.095)^0.5 -> 0.60129646 | AF74: =(Sheet1!G4275/0.237)/(Sheet1!S4275/0.17) -> 0.045445805 | AG74: =(Sheet1!M4275/0.2055)/(Sheet1!S4275/0.17) -> 0.77667767
...
